Traceback (most recent call last):
  File "/Users/eatai/.pyenv/versions/3.13.1/envs/datascience/lib/python3.13/site-packages/jupyter_cache/executors/utils.py", line 58, in single_nb_execution
    executenb(
    ~~~~~~~~~^
        nb,
        ^^^
    ...<4 lines>...
        **kwargs,
        ^^^^^^^^^
    )
    ^
  File "/Users/eatai/.pyenv/versions/3.13.1/envs/datascience/lib/python3.13/site-packages/nbclient/client.py", line 1319, in execute
    return NotebookClient(nb=nb, resources=resources, km=km, **kwargs).execute()
           ~~~~~~~~~~~~~~~~~~~~~~~~~~~~~~~~~~~~~~~~~~~~~~~~~~~~~~~~~~~~~~~~~~~^^
  File "/Users/eatai/.pyenv/versions/3.13.1/envs/datascience/lib/python3.13/site-packages/jupyter_core/utils/__init__.py", line 165, in wrapped
    return loop.run_until_complete(inner)
           ~~~~~~~~~~~~~~~~~~~~~~~^^^^^^^
  File "/Users/eatai/.pyenv/versions/3.13.1/lib/python3.13/asyncio/base_events.py", line 720, in run_until_complete
    return future.result()
           ~~~~~~~~~~~~~^^
  File "/Users/eatai/.pyenv/versions/3.13.1/envs/datascience/lib/python3.13/site-packages/nbclient/client.py", line 709, in async_execute
    await self.async_execute_cell(
        cell, index, execution_count=self.code_cells_executed + 1
    )
  File "/Users/eatai/.pyenv/versions/3.13.1/envs/datascience/lib/python3.13/site-packages/nbclient/client.py", line 1062, in async_execute_cell
    await self._check_raise_for_error(cell, cell_index, exec_reply)
  File "/Users/eatai/.pyenv/versions/3.13.1/envs/datascience/lib/python3.13/site-packages/nbclient/client.py", line 918, in _check_raise_for_error
    raise CellExecutionError.from_cell_and_msg(cell, exec_reply_content)
nbclient.exceptions.CellExecutionError: An error occurred while executing the following cell:
------------------
import requests
from PIL import Image
import numpy as np

url = "https://raw.githubusercontent.com/YugeTen/Computer-vision-CLAB2/master/peppers.png"

peppers_image = Image.open(url)
 
    
------------------


[0;31m---------------------------------------------------------------------------[0m
[0;31mFileNotFoundError[0m                         Traceback (most recent call last)
Cell [0;32mIn[1], line 7[0m
[1;32m      3[0m [38;5;28;01mimport[39;00m[38;5;250m [39m[38;5;21;01mnumpy[39;00m[38;5;250m [39m[38;5;28;01mas[39;00m[38;5;250m [39m[38;5;21;01mnp[39;00m
[1;32m      5[0m url [38;5;241m=[39m [38;5;124m"[39m[38;5;124mhttps://raw.githubusercontent.com/YugeTen/Computer-vision-CLAB2/master/peppers.png[39m[38;5;124m"[39m
[0;32m----> 7[0m peppers_image [38;5;241m=[39m [43mImage[49m[38;5;241;43m.[39;49m[43mopen[49m[43m([49m[43murl[49m[43m)[49m

File [0;32m~/.pyenv/versions/3.13.1/envs/datascience/lib/python3.13/site-packages/PIL/Image.py:3465[0m, in [0;36mopen[0;34m(fp, mode, formats)[0m
[1;32m   3462[0m     filename [38;5;241m=[39m os[38;5;241m.[39mfspath(fp)
[1;32m   3464[0m [38;5;28;01mif[39;00m filename:
[0;32m-> 3465[0m     fp [38;5;241m=[39m [43mbuiltins[49m[38;5;241;43m.[39;49m[43mopen[49m[43m([49m[43mfilename[49m[43m,[49m[43m [49m[38;5;124;43m"[39;49m[38;5;124;43mrb[39;49m[38;5;124;43m"[39;49m[43m)[49m
[1;32m   3466[0m     exclusive_fp [38;5;241m=[39m [38;5;28;01mTrue[39;00m
[1;32m   3467[0m [38;5;28;01melse[39;00m:

[0;31mFileNotFoundError[0m: [Errno 2] No such file or directory: 'https://raw.githubusercontent.com/YugeTen/Computer-vision-CLAB2/master/peppers.png'

