Traceback (most recent call last):
  File "/Users/eatai/.pyenv/versions/3.13.1/envs/datascience/lib/python3.13/site-packages/jupyter_cache/executors/utils.py", line 58, in single_nb_execution
    executenb(
    ~~~~~~~~~^
        nb,
        ^^^
    ...<4 lines>...
        **kwargs,
        ^^^^^^^^^
    )
    ^
  File "/Users/eatai/.pyenv/versions/3.13.1/envs/datascience/lib/python3.13/site-packages/nbclient/client.py", line 1319, in execute
    return NotebookClient(nb=nb, resources=resources, km=km, **kwargs).execute()
           ~~~~~~~~~~~~~~~~~~~~~~~~~~~~~~~~~~~~~~~~~~~~~~~~~~~~~~~~~~~~~~~~~~~^^
  File "/Users/eatai/.pyenv/versions/3.13.1/envs/datascience/lib/python3.13/site-packages/jupyter_core/utils/__init__.py", line 165, in wrapped
    return loop.run_until_complete(inner)
           ~~~~~~~~~~~~~~~~~~~~~~~^^^^^^^
  File "/Users/eatai/.pyenv/versions/3.13.1/lib/python3.13/asyncio/base_events.py", line 720, in run_until_complete
    return future.result()
           ~~~~~~~~~~~~~^^
  File "/Users/eatai/.pyenv/versions/3.13.1/envs/datascience/lib/python3.13/site-packages/nbclient/client.py", line 709, in async_execute
    await self.async_execute_cell(
        cell, index, execution_count=self.code_cells_executed + 1
    )
  File "/Users/eatai/.pyenv/versions/3.13.1/envs/datascience/lib/python3.13/site-packages/nbclient/client.py", line 1062, in async_execute_cell
    await self._check_raise_for_error(cell, cell_index, exec_reply)
  File "/Users/eatai/.pyenv/versions/3.13.1/envs/datascience/lib/python3.13/site-packages/nbclient/client.py", line 918, in _check_raise_for_error
    raise CellExecutionError.from_cell_and_msg(cell, exec_reply_content)
nbclient.exceptions.CellExecutionError: An error occurred while executing the following cell:
------------------
from sklearn.tree import DecisionTreeClassifier, plot_tree

tree_clf = DecisionTreeClassifier(max_depth = 4)
tree_clf.fit(X_train, y_train)

fig, ax = plt.subplots(1,1, figsize = (15, 6))
plot_tree(tree_clf,
          feature_names = feature_names,
          class_names = class_names,
          filled = True, fontsize = 12)
plt.show()
------------------


[0;31m---------------------------------------------------------------------------[0m
[0;31mNameError[0m                                 Traceback (most recent call last)
Cell [0;32mIn[8], line 4[0m
[1;32m      1[0m [38;5;28;01mfrom[39;00m[38;5;250m [39m[38;5;21;01msklearn[39;00m[38;5;21;01m.[39;00m[38;5;21;01mtree[39;00m[38;5;250m [39m[38;5;28;01mimport[39;00m DecisionTreeClassifier, plot_tree
[1;32m      3[0m tree_clf [38;5;241m=[39m DecisionTreeClassifier(max_depth [38;5;241m=[39m [38;5;241m4[39m)
[0;32m----> 4[0m tree_clf[38;5;241m.[39mfit([43mX_train[49m, y_train)
[1;32m      6[0m fig, ax [38;5;241m=[39m plt[38;5;241m.[39msubplots([38;5;241m1[39m,[38;5;241m1[39m, figsize [38;5;241m=[39m ([38;5;241m15[39m, [38;5;241m6[39m))
[1;32m      7[0m plot_tree(tree_clf,
[1;32m      8[0m           feature_names [38;5;241m=[39m feature_names,
[1;32m      9[0m           class_names [38;5;241m=[39m class_names,
[1;32m     10[0m           filled [38;5;241m=[39m [38;5;28;01mTrue[39;00m, fontsize [38;5;241m=[39m [38;5;241m12[39m)

[0;31mNameError[0m: name 'X_train' is not defined

