Traceback (most recent call last):
  File "/Users/eatai/.pyenv/versions/3.13.1/envs/datascience/lib/python3.13/site-packages/jupyter_cache/executors/utils.py", line 58, in single_nb_execution
    executenb(
    ~~~~~~~~~^
        nb,
        ^^^
    ...<4 lines>...
        **kwargs,
        ^^^^^^^^^
    )
    ^
  File "/Users/eatai/.pyenv/versions/3.13.1/envs/datascience/lib/python3.13/site-packages/nbclient/client.py", line 1319, in execute
    return NotebookClient(nb=nb, resources=resources, km=km, **kwargs).execute()
           ~~~~~~~~~~~~~~~~~~~~~~~~~~~~~~~~~~~~~~~~~~~~~~~~~~~~~~~~~~~~~~~~~~~^^
  File "/Users/eatai/.pyenv/versions/3.13.1/envs/datascience/lib/python3.13/site-packages/jupyter_core/utils/__init__.py", line 165, in wrapped
    return loop.run_until_complete(inner)
           ~~~~~~~~~~~~~~~~~~~~~~~^^^^^^^
  File "/Users/eatai/.pyenv/versions/3.13.1/lib/python3.13/asyncio/base_events.py", line 720, in run_until_complete
    return future.result()
           ~~~~~~~~~~~~~^^
  File "/Users/eatai/.pyenv/versions/3.13.1/envs/datascience/lib/python3.13/site-packages/nbclient/client.py", line 709, in async_execute
    await self.async_execute_cell(
        cell, index, execution_count=self.code_cells_executed + 1
    )
  File "/Users/eatai/.pyenv/versions/3.13.1/envs/datascience/lib/python3.13/site-packages/nbclient/client.py", line 1062, in async_execute_cell
    await self._check_raise_for_error(cell, cell_index, exec_reply)
  File "/Users/eatai/.pyenv/versions/3.13.1/envs/datascience/lib/python3.13/site-packages/nbclient/client.py", line 918, in _check_raise_for_error
    raise CellExecutionError.from_cell_and_msg(cell, exec_reply_content)
nbclient.exceptions.CellExecutionError: An error occurred while executing the following cell:
------------------
# from ucimlrepo import fetch_ucirepo 
  
# fetch dataset 
pd.read_csv('https://raw.githubusercontent.com/gaurav104/UCI---Mushroom-Classification/refs/heads/master/mushrooms.csv')
# data (as pandas dataframes) 
# X = mushroom.data.features 
# y = mushroom.data.targets 
  
# variable information 
# display(mushroom.variables[['name','description']]) 
------------------


[0;31m---------------------------------------------------------------------------[0m
[0;31mNameError[0m                                 Traceback (most recent call last)
Cell [0;32mIn[2], line 4[0m
[1;32m      1[0m [38;5;66;03m# from ucimlrepo import fetch_ucirepo [39;00m
[1;32m      2[0m   
[1;32m      3[0m [38;5;66;03m# fetch dataset [39;00m
[0;32m----> 4[0m [43mpd[49m[38;5;241m.[39mread_csv([38;5;124m'[39m[38;5;124mhttps://raw.githubusercontent.com/gaurav104/UCI---Mushroom-Classification/refs/heads/master/mushrooms.csv[39m[38;5;124m'[39m)
[1;32m      5[0m [38;5;66;03m# data (as pandas dataframes) [39;00m
[1;32m      6[0m [38;5;66;03m# X = mushroom.data.features [39;00m
[1;32m      7[0m [38;5;66;03m# y = mushroom.data.targets [39;00m
[1;32m      8[0m   
[1;32m      9[0m [38;5;66;03m# variable information [39;00m
[1;32m     10[0m [38;5;66;03m# display(mushroom.variables[['name','description']]) [39;00m

[0;31mNameError[0m: name 'pd' is not defined

