Traceback (most recent call last):
  File "/Users/eatai/.pyenv/versions/3.9.21/envs/tf/lib/python3.9/site-packages/jupyter_cache/executors/utils.py", line 58, in single_nb_execution
    executenb(
  File "/Users/eatai/.pyenv/versions/3.9.21/envs/tf/lib/python3.9/site-packages/nbclient/client.py", line 1319, in execute
    return NotebookClient(nb=nb, resources=resources, km=km, **kwargs).execute()
  File "/Users/eatai/.pyenv/versions/3.9.21/envs/tf/lib/python3.9/site-packages/jupyter_core/utils/__init__.py", line 165, in wrapped
    return loop.run_until_complete(inner)
  File "/Users/eatai/.pyenv/versions/3.9.21/lib/python3.9/asyncio/base_events.py", line 647, in run_until_complete
    return future.result()
  File "/Users/eatai/.pyenv/versions/3.9.21/envs/tf/lib/python3.9/site-packages/nbclient/client.py", line 709, in async_execute
    await self.async_execute_cell(
  File "/Users/eatai/.pyenv/versions/3.9.21/envs/tf/lib/python3.9/site-packages/nbclient/client.py", line 1062, in async_execute_cell
    await self._check_raise_for_error(cell, cell_index, exec_reply)
  File "/Users/eatai/.pyenv/versions/3.9.21/envs/tf/lib/python3.9/site-packages/nbclient/client.py", line 918, in _check_raise_for_error
    raise CellExecutionError.from_cell_and_msg(cell, exec_reply_content)
nbclient.exceptions.CellExecutionError: An error occurred while executing the following cell:
------------------
fig,ax = plt.subplots(len(models), 2, figsize = (10,30), sharex=True, sharey=True)

x_range = np.linspace(-1,1,100).reshape(-1,1)
y_true = my_poly(x_range)

for k, key in enumerate(models):
    reg = models[key]

    ax[k,0].scatter(x_train, y_train, s=10, color = 'teal')
    ax[k,0].plot(x_range, reg['y_model'], 'k--')
    ax[k,0].plot(x_range, y_range, 'r--', alpha = 0.3)

    ax[k,0].text(0.7,0.8, f'{reg['title']}\n$R^2 = ${reg["R2_train"]:.2}', transform=ax[k,0].transAxes)


    ax[k,0].set_ylim(my_ylims)

    ax[k,1].scatter(x_test, y_test, s=10, color = 'goldenrod')
    ax[k,1].plot(x_range, y_range, 'r--', alpha = 0.3)
    ax[k,1].plot(x_range, reg['y_model'], 'k--')  
    
    ax[k,1].text(0.7,0.8, f'$R^2 = ${reg["R2_test"]:.2}', transform=ax[k,1].transAxes)

ax[0,0].set_title('Training Set')
ax[0,1].set_title('Testing Set')
plt.show()
------------------


[0;36m  Cell [0;32mIn[8], line 13[0;36m[0m
[0;31m    ax[k,0].text(0.7,0.8, f'{reg['title']}\n$R^2 = ${reg["R2_train"]:.2}', transform=ax[k,0].transAxes)[0m
[0m                                  ^[0m
[0;31mSyntaxError[0m[0;31m:[0m f-string: unmatched '['


